Failure # 1 (occurred at 2025-04-26_00-01-22)
[36mray::PPO.train()[39m (pid=4126733, ip=10.127.30.131, actor_id=f6bfd755bb22d078ad280b5901000000, repr=PPO)
  File "/home/maryam.alshehyari/.local/lib/python3.8/site-packages/ray/tune/trainable/trainable.py", line 400, in train
    raise skipped from exception_cause(skipped)
  File "/home/maryam.alshehyari/.local/lib/python3.8/site-packages/ray/tune/trainable/trainable.py", line 397, in train
    result = self.step()
  File "/home/maryam.alshehyari/.local/lib/python3.8/site-packages/ray/rllib/algorithms/algorithm.py", line 853, in step
    results, train_iter_ctx = self._run_one_training_iteration()
  File "/home/maryam.alshehyari/.local/lib/python3.8/site-packages/ray/rllib/algorithms/algorithm.py", line 2838, in _run_one_training_iteration
    results = self.training_step()
  File "/home/maryam.alshehyari/.local/lib/python3.8/site-packages/ray/rllib/algorithms/ppo/ppo.py", line 429, in training_step
    train_batch = synchronous_parallel_sample(
  File "/home/maryam.alshehyari/.local/lib/python3.8/site-packages/ray/rllib/execution/rollout_ops.py", line 85, in synchronous_parallel_sample
    sample_batches = worker_set.foreach_worker(
  File "/home/maryam.alshehyari/.local/lib/python3.8/site-packages/ray/rllib/evaluation/worker_set.py", line 680, in foreach_worker
    handle_remote_call_result_errors(remote_results, self._ignore_worker_failures)
  File "/home/maryam.alshehyari/.local/lib/python3.8/site-packages/ray/rllib/evaluation/worker_set.py", line 76, in handle_remote_call_result_errors
    raise r.get()
ray.exceptions.RayTaskError(TypeError): [36mray::RolloutWorker.apply()[39m (pid=4126933, ip=10.127.30.131, actor_id=76aceffa301398635b7b385401000000, repr=<ray.rllib.evaluation.rollout_worker.RolloutWorker object at 0x7f0e66bf6c10>)
  File "/home/maryam.alshehyari/.local/lib/python3.8/site-packages/ray/rllib/utils/actor_manager.py", line 185, in apply
    raise e
  File "/home/maryam.alshehyari/.local/lib/python3.8/site-packages/ray/rllib/utils/actor_manager.py", line 176, in apply
    return func(self, *args, **kwargs)
  File "/home/maryam.alshehyari/.local/lib/python3.8/site-packages/ray/rllib/execution/rollout_ops.py", line 86, in <lambda>
    lambda w: w.sample(), local_worker=False, healthy_only=True
  File "/home/maryam.alshehyari/.local/lib/python3.8/site-packages/ray/rllib/evaluation/rollout_worker.py", line 696, in sample
    batches = [self.input_reader.next()]
  File "/home/maryam.alshehyari/.local/lib/python3.8/site-packages/ray/rllib/evaluation/sampler.py", line 92, in next
    batches = [self.get_data()]
  File "/home/maryam.alshehyari/.local/lib/python3.8/site-packages/ray/rllib/evaluation/sampler.py", line 277, in get_data
    item = next(self._env_runner)
  File "/home/maryam.alshehyari/.local/lib/python3.8/site-packages/ray/rllib/evaluation/env_runner_v2.py", line 344, in run
    outputs = self.step()
  File "/home/maryam.alshehyari/.local/lib/python3.8/site-packages/ray/rllib/evaluation/env_runner_v2.py", line 370, in step
    active_envs, to_eval, outputs = self._process_observations(
  File "/home/maryam.alshehyari/.local/lib/python3.8/site-packages/ray/rllib/evaluation/env_runner_v2.py", line 536, in _process_observations
    policy_id: PolicyID = episode.policy_for(agent_id)
  File "/home/maryam.alshehyari/.local/lib/python3.8/site-packages/ray/rllib/evaluation/episode_v2.py", line 120, in policy_for
    policy_id = self._agent_to_policy[agent_id] = self.policy_mapping_fn(
TypeError: mapping_fn() got an unexpected keyword argument 'worker'
